Workbook

Sheet INDEX
B3: TIME SERIES MODELING IN QUANTITATIVE FINANCE
B4: PART 1 OF 2 — Foundations & Excel Intuition | Part 2: Python Implementation
B5: ────────────────────────────────────────────────────────────────────────────────
B6: SERIES OVERVIEW
B7: This is a two-part project. Part 1 (this workbook) explains foundational concepts using a simulated illustrative return series and live Excel formulas. Part 2 (Python Jupyter notebook) applies every concept to real S&P 500 data, adds PACF and AIC/BIC model selection, and fits GARCH(1,1) via Maximum Likelihood. Start here; continue in Python.
B8: TAB | C8: CONCEPT | D8: WHAT YOU WILL UNDERSTAND | E8: NOTES
B9: 1 - RETURNS | C9: What are Financial Returns? | D9: Why we use log-returns, not prices; additivity across time | E9: '=LN(today/yesterday)*100 [built live in Excel]
B10: 2 - STYLIZED FACTS | C10: How Returns Actually Behave | D10: Fat tails, near-zero autocorrelation, volatility clustering | E10: Histogram, return chart, squared-returns chart
B11: 3 - STATIONARITY | C11: Why Prices Can't Be Modeled Directly | D11: What stationarity means and why returns satisfy it, prices don't | E11: Random walk vs. stationary process side-by-side
B12: 4 - AUTOCORRELATION | C12: Does the Past Predict the Future? | D12: ACF computed manually; raw returns vs. squared returns | E12: CORREL function, hand-built ACF bar chart
B13: 5 - ARIMA | C13: Modeling the Mean | D13: What AR, MA, and I each do in plain English; why ARIMA finds φ̂ ≈ −0.17 and R² ≈ 3% on a simulated illustrative series — ARIMA hands off to GARCH | E13: AR(1), MA(1), ARIMA(1,0,1) simulated & fitted to a simulated illustrative return series; fitted vs. actual charts
B14: 6 - GARCH MOTIVATION | C14: Volatility Modeling & Risk Measurement | D14: GARCH(1,1) captures variance clustering; daily VaR 95%/99% & Expected Shortfall derived from GARCH σ; Kupiec backtest confirms calibration; 3× vol range in the simulated series | E14: GARCH(1,1) recursion formula; VaR/ES time-series model; Kupiec backtest table; 5 embedded charts

Sheet 1.RETURNS
A2: SECTION 1 — WHAT ARE FINANCIAL RETURNS? [Prices below are a simulated illustrative series; base price = Dec 30, 2022; returns run Jan 3 – Dec 19, 2023]
A3: Date | B3: Price ($) | C3: Simple Return | D3: Log-Return | E3: Diff
A4: 30-Dec-2022 | B4: 4500 | C4: n/a | D4: n/a | F4: WHY DO WE USE RETURNS, NOT PRICES? | I4: ADDITIVITY PROOF — Read alongside the explanation box
A5: 03-Jan-2023 | B5: 4526.56 | C5: =B5/B4-1 -> 0.0059022222 | D5: =LN(B5/B4) -> 0.0058848723 | E5: =D5-C5 -> -1.7349878e-05 | I5: Day 1 log-return | J5: =LN(B5/B4)*100 -> 0.58848723
A6: 04-Jan-2023 | B6: 4521.08 | C6: =B6/B5-1 -> -0.0012106324 | D6: =LN(B6/B5) -> -0.0012113658 | E6: =D6-C6 -> -7.3340734e-07 | F6: A stock price on its own tells you almost nothing without context. | I6: Day 2 log-return | J6: =LN(B6/B5)*100 -> -0.12113658
A7: 05-Jan-2023 | B7: 4551.34 | C7: =B7/B6-1 -> 0.006693091 | D7: =LN(B7/B6) -> 0.0066707917 | E7: =D7-C7 -> -2.2299288e-05 | F7: A price of $4,500 is high for one stock and cheap for another. | I7: 2-day log-return (direct) | J7: =LN(B6/B4)*100 -> 0.46735066
A8: 06-Jan-2023 | B8: 4625.05 | C8: =B8/B7-1 -> 0.01619523 | D8: =LN(B8/B7) -> 0.016065487 | E8: =D8-C8 -> -0.0001297438 | F8: Returns — percentage changes from one day to the next — are | I8: Sum of day 1 + day 2 | J8: =J5+J6 -> 0.46735066
A9: 09-Jan-2023 | B9: 4613.71 | C9: =B9/B8-1 -> -0.0024518654 | D9: =LN(B9/B8) -> -0.0024548761 | E9: =D9-C9 -> -3.0107442e-06 | F9: comparable across time, across assets, and across markets. | I9: Are they equal? | J9: =IF(ABS(J7-J8)<0.0001,"YES — they are equal!","Check formulas") -> YES — they are equal! | L9: ← Should be YES
A10: 10-Jan-2023 | B10: 4604.44 | C10: =B10/B9-1 -> -0.002009229 | D10: =LN(B10/B9) -> -0.0020112502 | E10: =D10-C10 -> -2.0212085e-06
A11: 11-Jan-2023 | B11: 4675.59 | C11: =B11/B10-1 -> 0.015452476 | D11: =LN(B11/B10) -> 0.015334303 | E11: =D11-C11 -> -0.00011817368 | F11: WHY LOG-RETURNS SPECIFICALLY? | I11: SIMPLE RETURNS — Additivity Does NOT Hold
A12: 12-Jan-2023 | B12: 4717.27 | C12: =B12/B11-1 -> 0.008914383 | D12: =LN(B12/B11) -> 0.0088748844 | E12: =D12-C12 -> -3.9498549e-05 | I12: Day 1 simple return | J12: =(B5/B4-1)*100 -> 0.59022222
A13: 13-Jan-2023 | B13: 4694.58 | C13: =B13/B12-1 -> -0.0048099854 | D13: =LN(B13/B12) -> -0.0048215906 | E13: =D13-C13 -> -1.1605209e-05 | F13: The log-return is defined as: r_t = LN(P_t / P_{t-1}) × 100 | I13: Day 2 simple return | J13: =(B6/B5-1)*100 -> -0.12106324
A14: 16-Jan-2023 | B14: 4720.53 | C14: =B14/B13-1 -> 0.005527651 | D14: =LN(B14/B13) -> 0.0055124296 | E14: =D14-C14 -> -1.5221396e-05 | I14: 2-day simple return (direct) | J14: =(B6/B4-1)*100 -> 0.46844444
A15: 17-Jan-2023 | B15: 4700.32 | C15: =B15/B14-1 -> -0.0042812989 | D15: =LN(B15/B14) -> -0.0042904899 | E15: =D15-C15 -> -9.1910026e-06 | F15: Three reasons we prefer it over simple returns: | I15: Sum of day 1 + day 2 | J15: =J12+J13 -> 0.46915899
A16: 18-Jan-2023 | B16: 4680.56 | C16: =B16/B15-1 -> -0.0042039691 | D16: =LN(B16/B15) -> -0.0042128306 | E16: =D16-C16 -> -8.8615225e-06 | I16: Are they equal? | J16: =IF(ABS(J14-J15)<0.0001,"YES — they are equal!","NO — simple returns do NOT add!") -> NO — simple returns do NOT add! | L16: ← Should be NO
A17: 19-Jan-2023 | B17: 4692.73 | C17: =B17/B16-1 -> 0.0026001162 | D17: =LN(B17/B16) -> 0.0025967418 | E17: =D17-C17 -> -3.3744541e-06 | F17: 1. ADDITIVITY: Log-returns add up across time.
A18: 20-Jan-2023 | B18: 4603.62 | C18: =B18/B17-1 -> -0.018988947 | D18: =LN(B18/B17) -> -0.019171552 | E18: =D18-C18 -> -0.0001826054 | F18: A 5-day return = sum of 5 daily log-returns. Simple returns do not add.
A19: 23-Jan-2023 | B19: 4510.34 | C19: =B19/B18-1 -> -0.020262315 | D19: =LN(B19/B18) -> -0.020470412 | E19: =D19-C19 -> -0.00020809652
A20: 24-Jan-2023 | B20: 4481.22 | C20: =B20/B19-1 -> -0.006456276 | D20: =LN(B20/B19) -> -0.0064772079 | E20: =D20-C20 -> -2.0931893e-05 | F20: 2. SYMMETRY: A +10% log-return followed by -10% gets you back to the beginning.
A21: 25-Jan-2023 | B21: 4437.53 | C21: =B21/B20-1 -> -0.0097495771 | D21: =LN(B21/B20) -> -0.0097974154 | E21: =D21-C21 -> -4.7838317e-05 | F21: With simple returns, +10% then -10% loses you money (×1.10 × 0.90 = 0.99).
A22: 26-Jan-2023 | B22: 4453.62 | C22: =B22/B21-1 -> 0.003625891 | D22: =LN(B22/B21) -> 0.0036193333 | E22: =D22-C22 -> -6.5576958e-06
A23: 27-Jan-2023 | B23: 4414.81 | C23: =B23/B22-1 -> -0.0087142594 | D23: =LN(B23/B22) -> -0.0087524506 | E23: =D23-C23 -> -3.8191192e-05 | F23: 3. APPROXIMATION: For small daily moves (under ~2%), log ≈ simple return.
A24: 30-Jan-2023 | B24: 4352.34 | C24: =B24/B23-1 -> -0.014150099 | D24: =LN(B24/B23) -> -0.014251167 | E24: =D24-C24 -> -0.0001010672 | F24: So we get all the math benefits at almost no practical cost.
A25: 31-Jan-2023 | B25: 4425.34 | C25: =B25/B24-1 -> 0.016772587 | D25: =LN(B25/B24) -> 0.01663348 | E25: =D25-C25 -> -0.00013910654
A26: 01-Feb-2023 | B26: 4415.05 | C26: =B26/B25-1 -> -0.0023252451 | D26: =LN(B26/B25) -> -0.0023279526 | E26: =D26-C26 -> -2.7075803e-06 | F26: SEE THE DATA TABLE TO THE LEFT →
A27: 02-Feb-2023 | B27: 4419.19 | C27: =B27/B26-1 -> 0.00093770172 | D27: =LN(B27/B26) -> 0.00093726236 | E27: =D27-C27 -> -4.3936762e-07 | F27: Look at how Column D (log-return) and Column E (simple return) compare.
A28: 03-Feb-2023 | B28: 4359.34 | C28: =B28/B27-1 -> -0.013543206 | D28: =LN(B28/B27) -> -0.013635752 | E28: =D28-C28 -> -9.254574e-05 | F28: On normal days they are nearly identical. This confirms the approximation.
A29: 06-Feb-2023 | B29: 4335.03 | C29: =B29/B28-1 -> -0.0055765322 | D29: =LN(B29/B28) -> -0.0055921391 | E29: =D29-C29 -> -1.5606904e-05
A30: 07-Feb-2023 | B30: 4341.04 | C30: =B30/B29-1 -> 0.0013863803 | D30: =LN(B30/B29) -> 0.0013854201 | E30: =D30-C30 -> -9.601378e-07 | F30: LIVE PROOF: Additivity of Log-Returns (see rows 7-10 in data)
A31: 08-Feb-2023 | B31: 4293.48 | C31: =B31/B30-1 -> -0.0109559 | D31: =LN(B31/B30) -> -0.011016358 | E31: =D31-C31 -> -6.0457858e-05 | F31: Cell D9 = LN(C9/C8)*100 ← 1-day log-return
A32: 09-Feb-2023 | B32: 4312.13 | C32: =B32/B31-1 -> 0.0043437957 | D32: =LN(B32/B31) -> 0.0043343887 | E32: =D32-C32 -> -9.4070489e-06 | F32: Cell D10 = LN(C10/C9)*100 ← next 1-day log-return
A33: 10-Feb-2023 | B33: 4286.49 | C33: =B33/B32-1 -> -0.0059460174 | D33: =LN(B33/B32) -> -0.0059637653 | E33: =D33-C33 -> -1.7747949e-05 | F33: Cell D11 = LN(C10/C8)*100 ← 2-day log-return
A34: 13-Feb-2023 | B34: 4274.65 | C34: =B34/B33-1 -> -0.0027621667 | D34: =LN(B34/B33) -> -0.0027659885 | E34: =D34-C34 -> -3.8218218e-06 | F34: Notice: D9 + D10 = D11 (exactly, to many decimal places)
A35: 14-Feb-2023 | B35: 4251.31 | C35: =B35/B34-1 -> -0.0054600961 | D35: =LN(B35/B34) -> -0.005475057 | E35: =D35-C35 -> -1.4960808e-05 | F35: This is the additivity property. Simple returns do NOT have this.
A36: 15-Feb-2023 | B36: 4330.29 | C36: =B36/B35-1 -> 0.018577803 | D36: =LN(B36/B35) -> 0.018407344 | E36: =D36-C36 -> -0.00017045945
A37: 16-Feb-2023 | B37: 4330.67 | C37: =B37/B36-1 -> 8.7753938e-05 | D37: =LN(B37/B36) -> 8.7750088e-05 | E37: =D37-C37 -> -3.8501516e-09
A38: 17-Feb-2023 | B38: 4290.34 | C38: =B38/B37-1 -> -0.0093126468 | D38: =LN(B38/B37) -> -0.0093562806 | E38: =D38-C38 -> -4.3633804e-05
A39: 20-Feb-2023 | B39: 4329.48 | C39: =B39/B38-1 -> 0.0091228201 | D39: =LN(B39/B38) -> 0.0090814585 | E39: =D39-C39 -> -4.1361558e-05
A40: 21-Feb-2023 | B40: 4272.75 | C40: =B40/B39-1 -> -0.01310319 | D40: =LN(B40/B39) -> -0.013189794 | E40: =D40-C40 -> -8.6604156e-05
A41: 22-Feb-2023 | B41: 4283.83 | C41: =B41/B40-1 -> 0.0025931777 | D41: =LN(B41/B40) -> 0.0025898212 | E41: =D41-C41 -> -3.3564839e-06
...

Sheet 2.STYLIZED FACTS
A2: SECTION 2 — STYLIZED FACTS: HOW FINANCIAL RETURNS ACTUALLY BEHAVE
B3: Date | C3: Log-Return (%) | D3: Squared Return | E3: Abs Return | I3: HISTOGRAM BINS | O3: SCATTER DATA
B4: 30-Dec-2022 | D4: =C4^2 -> 0 | E4: =ABS(C4) -> 0 | G4: WHAT ARE STYLIZED FACTS? | I4: Bin Low | J4: Bin High | K4: Return Range | L4: Actual Count | M4: Normal Expected | O4: r(t-1) | P4: r(t)
B5: 03-Jan-2023 | C5: ='1.RETURNS'!D5 -> 0.0058848723 | D5: =C5^2 -> 3.4631723e-05 | E5: =ABS(C5) -> 0.0058848723 | I5: -0.05 | J5: -0.045 | K5: -4.75% | L5: =COUNTIF($C$5:$C$255,"<"&J5) -> 0 | M5: =COUNT($C$5:$C$255)*_xlfn.NORM.DIST(J5,AVERAGE($C$5:$C$255),STDEV($C$5:$C$255),TRUE) -> 0.0060340321
B6: 04-Jan-2023 | C6: ='1.RETURNS'!D6 -> -0.0012113658 | D6: =C6^2 -> 1.467407e-06 | E6: =ABS(C6) -> 0.0012113658 | G6: Across nearly every financial market and time period, return series | I6: -0.045 | J6: -0.04 | K6: -4.25% | L6: =COUNTIFS($C$5:$C$255,">="&I6,$C$5:$C$255,"<"&J6) -> 1 | M6: =COUNT($C$5:$C$255)*(_xlfn.NORM.DIST(J6,AVERAGE($C$5:$C$255),STDEV($C$5:$C$255),TRUE)-_xlfn.NORM.DIST(I6,AVERAGE($C$5:$C$255),STDEV($C$5:$C$255),TRUE)) -> 0.032267217 | O6: =C5 -> 0.0058848723 | P6: =C6 -> -0.0012113658
B7: 05-Jan-2023 | C7: ='1.RETURNS'!D7 -> 0.0066707917 | D7: =C7^2 -> 4.4499462e-05 | E7: =ABS(C7) -> 0.0066707917 | G7: share the same surprising statistical properties. These are not | I7: -0.04 | J7: -0.035 | K7: -3.75% | L7: =COUNTIFS($C$5:$C$255,">="&I7,$C$5:$C$255,"<"&J7) -> 1 | M7: =COUNT($C$5:$C$255)*(_xlfn.NORM.DIST(J7,AVERAGE($C$5:$C$255),STDEV($C$5:$C$255),TRUE)-_xlfn.NORM.DIST(I7,AVERAGE($C$5:$C$255),STDEV($C$5:$C$255),TRUE)) -> 0.1617883 | O7: =C6 -> -0.0012113658 | P7: =C7 -> 0.0066707917
B8: 06-Jan-2023 | C8: ='1.RETURNS'!D8 -> 0.016065487 | D8: =C8^2 -> 0.00025809986 | E8: =ABS(C8) -> 0.016065487 | G8: theoretical predictions — they are empirical regularities observed | I8: -0.035 | J8: -0.03 | K8: -3.25% | L8: =COUNTIFS($C$5:$C$255,">="&I8,$C$5:$C$255,"<"&J8) -> 1 | M8: =COUNT($C$5:$C$255)*(_xlfn.NORM.DIST(J8,AVERAGE($C$5:$C$255),STDEV($C$5:$C$255),TRUE)-_xlfn.NORM.DIST(I8,AVERAGE($C$5:$C$255),STDEV($C$5:$C$255),TRUE)) -> 0.66223845 | O8: =C7 -> 0.0066707917 | P8: =C8 -> 0.016065487
B9: 09-Jan-2023 | C9: ='1.RETURNS'!D9 -> -0.0024548761 | D9: =C9^2 -> 6.0264168e-06 | E9: =ABS(C9) -> 0.0024548761 | G9: in real data and documented by researchers for decades. | I9: -0.03 | J9: -0.025 | K9: -2.75% | L9: =COUNTIFS($C$5:$C$255,">="&I9,$C$5:$C$255,"<"&J9) -> 1 | M9: =COUNT($C$5:$C$255)*(_xlfn.NORM.DIST(J9,AVERAGE($C$5:$C$255),STDEV($C$5:$C$255),TRUE)-_xlfn.NORM.DIST(I9,AVERAGE($C$5:$C$255),STDEV($C$5:$C$255),TRUE)) -> 2.2131015 | O9: =C8 -> 0.016065487 | P9: =C9 -> -0.0024548761
B10: 10-Jan-2023 | C10: ='1.RETURNS'!D10 -> -0.0020112502 | D10: =C10^2 -> 4.0451275e-06 | E10: =ABS(C10) -> 0.0020112502 | I10: -0.025 | J10: -0.02 | K10: -2.25% | L10: =COUNTIFS($C$5:$C$255,">="&I10,$C$5:$C$255,"<"&J10) -> 4 | M10: =COUNT($C$5:$C$255)*(_xlfn.NORM.DIST(J10,AVERAGE($C$5:$C$255),STDEV($C$5:$C$255),TRUE)-_xlfn.NORM.DIST(I10,AVERAGE($C$5:$C$255),STDEV($C$5:$C$255),TRUE)) -> 6.0386762 | O10: =C9 -> -0.0024548761 | P10: =C10 -> -0.0020112502
B11: 11-Jan-2023 | C11: ='1.RETURNS'!D11 -> 0.015334303 | D11: =C11^2 -> 0.00023514084 | E11: =ABS(C11) -> 0.015334303 | G11: THE 4 KEY STYLIZED FACTS WE COVER HERE: | I11: -0.02 | J11: -0.015 | K11: -1.75% | L11: =COUNTIFS($C$5:$C$255,">="&I11,$C$5:$C$255,"<"&J11) -> 11 | M11: =COUNT($C$5:$C$255)*(_xlfn.NORM.DIST(J11,AVERAGE($C$5:$C$255),STDEV($C$5:$C$255),TRUE)-_xlfn.NORM.DIST(I11,AVERAGE($C$5:$C$255),STDEV($C$5:$C$255),TRUE)) -> 13.454415 | O11: =C10 -> -0.0020112502 | P11: =C11 -> 0.015334303
B12: 12-Jan-2023 | C12: ='1.RETURNS'!D12 -> 0.0088748844 | D12: =C12^2 -> 7.8763574e-05 | E12: =ABS(C12) -> 0.0088748844 | I12: -0.015 | J12: -0.01 | K12: -1.25% | L12: =COUNTIFS($C$5:$C$255,">="&I12,$C$5:$C$255,"<"&J12) -> 21 | M12: =COUNT($C$5:$C$255)*(_xlfn.NORM.DIST(J12,AVERAGE($C$5:$C$255),STDEV($C$5:$C$255),TRUE)-_xlfn.NORM.DIST(I12,AVERAGE($C$5:$C$255),STDEV($C$5:$C$255),TRUE)) -> 24.479046 | O12: =C11 -> 0.015334303 | P12: =C12 -> 0.0088748844
B13: 13-Jan-2023 | C13: ='1.RETURNS'!D13 -> -0.0048215906 | D13: =C13^2 -> 2.3247736e-05 | E13: =ABS(C13) -> 0.0048215906 | G13: FACT 1 — RETURNS LOOK LIKE RANDOM NOISE | I13: -0.01 | J13: -0.005 | K13: -0.75% | L13: =COUNTIFS($C$5:$C$255,">="&I13,$C$5:$C$255,"<"&J13) -> 41 | M13: =COUNT($C$5:$C$255)*(_xlfn.NORM.DIST(J13,AVERAGE($C$5:$C$255),STDEV($C$5:$C$255),TRUE)-_xlfn.NORM.DIST(I13,AVERAGE($C$5:$C$255),STDEV($C$5:$C$255),TRUE)) -> 36.370484 | O13: =C12 -> 0.0088748844 | P13: =C13 -> -0.0048215906
B14: 16-Jan-2023 | C14: ='1.RETURNS'!D14 -> 0.0055124296 | D14: =C14^2 -> 3.0386881e-05 | E14: =ABS(C14) -> 0.0055124296 | G14: Plot Column D (log-returns) over time. It oscillates around zero | I14: -0.005 | J14: 0 | K14: -0.25% | L14: =COUNTIFS($C$5:$C$255,">="&I14,$C$5:$C$255,"<"&J14) -> 41 | M14: =COUNT($C$5:$C$255)*(_xlfn.NORM.DIST(J14,AVERAGE($C$5:$C$255),STDEV($C$5:$C$255),TRUE)-_xlfn.NORM.DIST(I14,AVERAGE($C$5:$C$255),STDEV($C$5:$C$255),TRUE)) -> 44.130709 | O14: =C13 -> -0.0048215906 | P14: =C14 -> 0.0055124296
B15: 17-Jan-2023 | C15: ='1.RETURNS'!D15 -> -0.0042904899 | D15: =C15^2 -> 1.8408304e-05 | E15: =ABS(C15) -> 0.0042904899 | G15: with no clear trend. There is no direction to predict. This is | I15: 0 | J15: 0.005 | K15: 0.25% | L15: =COUNTIFS($C$5:$C$255,">="&I15,$C$5:$C$255,"<"&J15) -> 53 | M15: =COUNT($C$5:$C$255)*(_xlfn.NORM.DIST(J15,AVERAGE($C$5:$C$255),STDEV($C$5:$C$255),TRUE)-_xlfn.NORM.DIST(I15,AVERAGE($C$5:$C$255),STDEV($C$5:$C$255),TRUE)) -> 43.729655 | O15: =C14 -> 0.0055124296 | P15: =C15 -> -0.0042904899
B16: 18-Jan-2023 | C16: ='1.RETURNS'!D16 -> -0.0042128306 | D16: =C16^2 -> 1.7747942e-05 | E16: =ABS(C16) -> 0.0042128306 | G16: consistent with the efficient market idea: prices already reflect | I16: 0.005 | J16: 0.01 | K16: 0.75% | L16: =COUNTIFS($C$5:$C$255,">="&I16,$C$5:$C$255,"<"&J16) -> 38 | M16: =COUNT($C$5:$C$255)*(_xlfn.NORM.DIST(J16,AVERAGE($C$5:$C$255),STDEV($C$5:$C$255),TRUE)-_xlfn.NORM.DIST(I16,AVERAGE($C$5:$C$255),STDEV($C$5:$C$255),TRUE)) -> 35.387853 | O16: =C15 -> -0.0042904899 | P16: =C16 -> -0.0042128306
B17: 19-Jan-2023 | C17: ='1.RETURNS'!D17 -> 0.0025967418 | D17: =C17^2 -> 6.7430678e-06 | E17: =ABS(C17) -> 0.0025967418 | G17: available information. | I17: 0.01 | J17: 0.015 | K17: 1.25% | L17: =COUNTIFS($C$5:$C$255,">="&I17,$C$5:$C$255,"<"&J17) -> 19 | M17: =COUNT($C$5:$C$255)*(_xlfn.NORM.DIST(J17,AVERAGE($C$5:$C$255),STDEV($C$5:$C$255),TRUE)-_xlfn.NORM.DIST(I17,AVERAGE($C$5:$C$255),STDEV($C$5:$C$255),TRUE)) -> 23.38669 | O17: =C16 -> -0.0042128306 | P17: =C17 -> 0.0025967418
B18: 20-Jan-2023 | C18: ='1.RETURNS'!D18 -> -0.019171552 | D18: =C18^2 -> 0.00036754841 | E18: =ABS(C18) -> 0.019171552 | I18: 0.015 | J18: 0.02 | K18: 1.75% | L18: =COUNTIFS($C$5:$C$255,">="&I18,$C$5:$C$255,"<"&J18) -> 12 | M18: =COUNT($C$5:$C$255)*(_xlfn.NORM.DIST(J18,AVERAGE($C$5:$C$255),STDEV($C$5:$C$255),TRUE)-_xlfn.NORM.DIST(I18,AVERAGE($C$5:$C$255),STDEV($C$5:$C$255),TRUE)) -> 12.621379 | O18: =C17 -> 0.0025967418 | P18: =C18 -> -0.019171552
B19: 23-Jan-2023 | C19: ='1.RETURNS'!D19 -> -0.020470412 | D19: =C19^2 -> 0.00041903776 | E19: =ABS(C19) -> 0.020470412 | G19: FACT 2 — FAT TAILS (Leptokurtosis) | I19: 0.02 | J19: 0.025 | K19: 2.25% | L19: =COUNTIFS($C$5:$C$255,">="&I19,$C$5:$C$255,"<"&J19) -> 4 | M19: =COUNT($C$5:$C$255)*(_xlfn.NORM.DIST(J19,AVERAGE($C$5:$C$255),STDEV($C$5:$C$255),TRUE)-_xlfn.NORM.DIST(I19,AVERAGE($C$5:$C$255),STDEV($C$5:$C$255),TRUE)) -> 5.5622379 | O19: =C18 -> -0.019171552 | P19: =C19 -> -0.020470412
B20: 24-Jan-2023 | C20: ='1.RETURNS'!D20 -> -0.0064772079 | D20: =C20^2 -> 4.1954222e-05 | E20: =ABS(C20) -> 0.0064772079 | G20: Plot a histogram of Column D. Compare it to a normal bell curve. | I20: 0.025 | J20: 0.03 | K20: 2.75% | L20: =COUNTIFS($C$5:$C$255,">="&I20,$C$5:$C$255,"<"&J20) -> 2 | M20: =COUNT($C$5:$C$255)*(_xlfn.NORM.DIST(J20,AVERAGE($C$5:$C$255),STDEV($C$5:$C$255),TRUE)-_xlfn.NORM.DIST(I20,AVERAGE($C$5:$C$255),STDEV($C$5:$C$255),TRUE)) -> 2.001578 | O20: =C19 -> -0.020470412 | P20: =C20 -> -0.0064772079
B21: 25-Jan-2023 | C21: ='1.RETURNS'!D21 -> -0.0097974154 | D21: =C21^2 -> 9.5989349e-05 | E21: =ABS(C21) -> 0.0097974154 | G21: The return distribution has a taller, sharper peak and FATTER tails. | I21: 0.03 | J21: 0.035 | K21: 3.25% | L21: =COUNTIFS($C$5:$C$255,">="&I21,$C$5:$C$255,"<"&J21) -> 0 | M21: =COUNT($C$5:$C$255)*(_xlfn.NORM.DIST(J21,AVERAGE($C$5:$C$255),STDEV($C$5:$C$255),TRUE)-_xlfn.NORM.DIST(I21,AVERAGE($C$5:$C$255),STDEV($C$5:$C$255),TRUE)) -> 0.5880931 | O21: =C20 -> -0.0064772079 | P21: =C21 -> -0.0097974154
B22: 26-Jan-2023 | C22: ='1.RETURNS'!D22 -> 0.0036193333 | D22: =C22^2 -> 1.3099573e-05 | E22: =ABS(C22) -> 0.0036193333 | G22: Extreme moves (-3%, -4%, -5%) happen far more often than a normal | I22: 0.035 | J22: 0.04 | K22: 3.75% | L22: =COUNTIFS($C$5:$C$255,">="&I22,$C$5:$C$255,"<"&J22) -> 0 | M22: =COUNT($C$5:$C$255)*(_xlfn.NORM.DIST(J22,AVERAGE($C$5:$C$255),STDEV($C$5:$C$255),TRUE)-_xlfn.NORM.DIST(I22,AVERAGE($C$5:$C$255),STDEV($C$5:$C$255),TRUE)) -> 0.14107045 | O22: =C21 -> -0.0097974154 | P22: =C22 -> 0.0036193333
B23: 27-Jan-2023 | C23: ='1.RETURNS'!D23 -> -0.0087524506 | D23: =C23^2 -> 7.6605392e-05 | E23: =ABS(C23) -> 0.0087524506 | G23: distribution would predict. This is the #1 reason risk models that | I23: 0.04 | J23: 0.045 | K23: 4.25% | L23: =COUNTIFS($C$5:$C$255,">="&I23,$C$5:$C$255,"<"&J23) -> 1 | M23: =COUNT($C$5:$C$255)*(_xlfn.NORM.DIST(J23,AVERAGE($C$5:$C$255),STDEV($C$5:$C$255),TRUE)-_xlfn.NORM.DIST(I23,AVERAGE($C$5:$C$255),STDEV($C$5:$C$255),TRUE)) -> 0.027625115 | O23: =C22 -> 0.0036193333 | P23: =C23 -> -0.0087524506
B24: 30-Jan-2023 | C24: ='1.RETURNS'!D24 -> -0.014251167 | D24: =C24^2 -> 0.00020309575 | E24: =ABS(C24) -> 0.014251167 | G24: assume normality underestimate actual tail losses. | I24: 0.045 | J24: 0.05 | K24: 4.75% | L24: =COUNTIF($C$5:$C$255,">="&I24) -> 0 | M24: =COUNT($C$5:$C$255)*(1-_xlfn.NORM.DIST(I24,AVERAGE($C$5:$C$255),STDEV($C$5:$C$255),TRUE)) -> 0.0050589716 | O24: =C23 -> -0.0087524506 | P24: =C24 -> -0.014251167
B25: 31-Jan-2023 | C25: ='1.RETURNS'!D25 -> 0.01663348 | D25: =C25^2 -> 0.00027667266 | E25: =ABS(C25) -> 0.01663348 | O25: =C24 -> -0.014251167 | P25: =C25 -> 0.01663348
B26: 01-Feb-2023 | C26: ='1.RETURNS'!D26 -> -0.0023279526 | D26: =C26^2 -> 5.4193635e-06 | E26: =ABS(C26) -> 0.0023279526 | G26: FACT 3 — SMALL AUTOCORRELATION IN RAW RETURNS | O26: =C25 -> 0.01663348 | P26: =C26 -> -0.0023279526
B27: 02-Feb-2023 | C27: ='1.RETURNS'!D27 -> 0.00093726236 | D27: =C27^2 -> 8.7846073e-07 | E27: =ABS(C27) -> 0.00093726236 | G27: Today's return gives very little information about tomorrow's return. | O27: =C26 -> -0.0023279526 | P27: =C27 -> 0.00093726236
B28: 03-Feb-2023 | C28: ='1.RETURNS'!D28 -> -0.013635752 | D28: =C28^2 -> 0.00018593372 | E28: =ABS(C28) -> 0.013635752 | G28: We will measure this precisely in Section 4 (Autocorrelation). | O28: =C27 -> 0.00093726236 | P28: =C28 -> -0.013635752
B29: 06-Feb-2023 | C29: ='1.RETURNS'!D29 -> -0.0055921391 | D29: =C29^2 -> 3.127202e-05 | E29: =ABS(C29) -> 0.0055921391 | G29: For now: this is why ARIMA will find almost nothing to model. | O29: =C28 -> -0.013635752 | P29: =C29 -> -0.0055921391
B30: 07-Feb-2023 | C30: ='1.RETURNS'!D30 -> 0.0013854201 | D30: =C30^2 -> 1.9193889e-06 | E30: =ABS(C30) -> 0.0013854201 | O30: =C29 -> -0.0055921391 | P30: =C30 -> 0.0013854201
B31: 08-Feb-2023 | C31: ='1.RETURNS'!D31 -> -0.011016358 | D31: =C31^2 -> 0.00012136014 | E31: =ABS(C31) -> 0.011016358 | G31: FACT 4 — VOLATILITY CLUSTERING (the most important one) | O31: =C30 -> 0.0013854201 | P31: =C31 -> -0.011016358
B32: 09-Feb-2023 | C32: ='1.RETURNS'!D32 -> 0.0043343887 | D32: =C32^2 -> 1.8786925e-05 | E32: =ABS(C32) -> 0.0043343887 | G32: Look at Column E (squared returns). Squaring removes the sign | O32: =C31 -> -0.011016358 | P32: =C32 -> 0.0043343887
B33: 10-Feb-2023 | C33: ='1.RETURNS'!D33 -> -0.0059637653 | D33: =C33^2 -> 3.5566497e-05 | E33: =ABS(C33) -> 0.0059637653 | G33: and leaves only the magnitude. Now you can see clusters of large | O33: =C32 -> 0.0043343887 | P33: =C33 -> -0.0059637653
B34: 13-Feb-2023 | C34: ='1.RETURNS'!D34 -> -0.0027659885 | D34: =C34^2 -> 7.6506926e-06 | E34: =ABS(C34) -> 0.0027659885 | G34: values followed by more large values — calm follows calm, | O34: =C33 -> -0.0059637653 | P34: =C34 -> -0.0027659885
B35: 14-Feb-2023 | C35: ='1.RETURNS'!D35 -> -0.005475057 | D35: =C35^2 -> 2.9976249e-05 | E35: =ABS(C35) -> 0.005475057 | G35: turbulence follows turbulence. This is NOT random. This is the | O35: =C34 -> -0.0027659885 | P35: =C35 -> -0.005475057
B36: 15-Feb-2023 | C36: ='1.RETURNS'!D36 -> 0.018407344 | D36: =C36^2 -> 0.0003388303 | E36: =ABS(C36) -> 0.018407344 | G36: structure GARCH is built to capture. | O36: =C35 -> -0.005475057 | P36: =C36 -> 0.018407344
B37: 16-Feb-2023 | C37: ='1.RETURNS'!D37 -> 8.7750088e-05 | D37: =C37^2 -> 7.7000779e-09 | E37: =ABS(C37) -> 8.7750088e-05 | O37: =C36 -> 0.018407344 | P37: =C37 -> 8.7750088e-05
B38: 17-Feb-2023 | C38: ='1.RETURNS'!D38 -> -0.0093562806 | D38: =C38^2 -> 8.7539986e-05 | E38: =ABS(C38) -> 0.0093562806 | G38: WHY DOES CLUSTERING MATTER FOR RISK? | O38: =C37 -> 8.7750088e-05 | P38: =C38 -> -0.0093562806
B39: 20-Feb-2023 | C39: ='1.RETURNS'!D39 -> 0.0090814585 | D39: =C39^2 -> 8.2472889e-05 | E39: =ABS(C39) -> 0.0090814585 | G39: Because if volatility is predictable, so is risk. | O39: =C38 -> -0.0093562806 | P39: =C39 -> 0.0090814585
B40: 21-Feb-2023 | C40: ='1.RETURNS'!D40 -> -0.013189794 | D40: =C40^2 -> 0.00017397068 | E40: =ABS(C40) -> 0.013189794 | G40: A GARCH model uses this clustering to forecast tomorrow's | O40: =C39 -> 0.0090814585 | P40: =C40 -> -0.013189794
B41: 22-Feb-2023 | C41: ='1.RETURNS'!D41 -> 0.0025898212 | D41: =C41^2 -> 6.7071739e-06 | E41: =ABS(C41) -> 0.0025898212 | G41: expected volatility — and therefore tomorrow's risk. | O41: =C40 -> -0.013189794 | P41: =C41 -> 0.0025898212
...

Sheet 3.STATIONARITY
B2: SECTION 3 — STATIONARITY: WHY PRICES CAN'T BE MODELED DIRECTLY
B3: Obs # | C3: Random Shock (ε) | D3: Random Walk (cumsum) | E3: 1st Diff of Walk | F3: Simulated Return (%) | G3: Simulated Cum. Level (Idx=100)
B4: 1 | C4: =_xlfn.NORM.S.INV(RAND()) -> -0.38383894 | D4: =C4 -> -0.38383894 | E4: n/a | F4: n/a | G4: 100 | H4: WHAT IS STATIONARITY?
B5: 2 | C5: =_xlfn.NORM.S.INV(RAND()) -> -0.58489192 | D5: =D4+C5 -> -0.96873086 | E5: =D5-D4 -> -0.58489192 | F5: ='1.RETURNS'!D5 -> 0.0058848723 | G5: =G4*EXP(F5) -> 100.59022
B6: 3 | C6: =_xlfn.NORM.S.INV(RAND()) -> -1.2132108 | D6: =D5+C6 -> -2.1819417 | E6: =D6-D5 -> -1.2132108 | F6: ='1.RETURNS'!D6 -> -0.0012113658 | G6: =G5*EXP(F6) -> 100.46844 | H6: A time series is stationary if its statistical properties — mean,
B7: 4 | C7: =_xlfn.NORM.S.INV(RAND()) -> -1.4998538 | D7: =D6+C7 -> -3.6817955 | E7: =D7-D6 -> -1.4998538 | F7: ='1.RETURNS'!D7 -> 0.0066707917 | G7: =G6*EXP(F7) -> 101.14089 | H7: variance, and autocorrelation structure — do not change over time.
B8: 5 | C8: =_xlfn.NORM.S.INV(RAND()) -> 1.0809506 | D8: =D7+C8 -> -2.6008449 | E8: =D8-D7 -> 1.0809506 | F8: ='1.RETURNS'!D8 -> 0.016065487 | G8: =G7*EXP(F8) -> 102.77889 | T8: The Core Problem: Why You Can't Model Stock Prices Directly
B9: 6 | C9: =_xlfn.NORM.S.INV(RAND()) -> -1.3642157 | D9: =D8+C9 -> -3.9650606 | E9: =D9-D8 -> -1.3642157 | F9: ='1.RETURNS'!D9 -> -0.0024548761 | G9: =G8*EXP(F9) -> 102.52689 | H9: Think of it this way:
B10: 7 | C10: =_xlfn.NORM.S.INV(RAND()) -> 0.28407338 | D10: =D9+C10 -> -3.6809872 | E10: =D10-D9 -> 0.28407338 | F10: ='1.RETURNS'!D10 -> -0.0020112502 | G10: =G9*EXP(F10) -> 102.32089 | H10: A stationary series bounces around a fixed center. | T10: Most time series models (ARIMA, regression, VAR) have one fundamental requirement: the data must be stationary — meaning its mean, variance, and autocorrelation structure don't change over time.
B11: 8 | C11: =_xlfn.NORM.S.INV(RAND()) -> 0.71414913 | D11: =D10+C11 -> -2.9668381 | E11: =D11-D10 -> 0.71414913 | F11: ='1.RETURNS'!D11 -> 0.015334303 | G11: =G10*EXP(F11) -> 103.902 | H11: A non-stationary series drifts — it wanders off and never
B12: 9 | C12: =_xlfn.NORM.S.INV(RAND()) -> 0.52647562 | D12: =D11+C12 -> -2.4403625 | E12: =D12-D11 -> 0.52647562 | F12: ='1.RETURNS'!D12 -> 0.0088748844 | G12: =G11*EXP(F12) -> 104.82822 | H12: comes back to any particular level. | T12: Stock prices violate this. They drift — permanently. There's no level they "return to."
B13: 10 | C13: =_xlfn.NORM.S.INV(RAND()) -> 0.38866945 | D13: =D12+C13 -> -2.051693 | E13: =D13-D12 -> 0.38866945 | F13: ='1.RETURNS'!D13 -> -0.0048215906 | G13: =G12*EXP(F13) -> 104.324
B14: 11 | C14: =_xlfn.NORM.S.INV(RAND()) -> 0.44948214 | D14: =D13+C14 -> -1.6022109 | E14: =D14-D13 -> 0.44948214 | F14: ='1.RETURNS'!D14 -> 0.0055124296 | G14: =G13*EXP(F14) -> 104.90067 | H14: WHY DOES IT MATTER?
B15: 12 | C15: =_xlfn.NORM.S.INV(RAND()) -> 3.2237578 | D15: =D14+C15 -> 1.6215469 | E15: =D15-D14 -> 3.2237578 | F15: ='1.RETURNS'!D15 -> -0.0042904899 | G15: =G14*EXP(F15) -> 104.45156
B16: 13 | C16: =_xlfn.NORM.S.INV(RAND()) -> -0.40261467 | D16: =D15+C16 -> 1.2189322 | E16: =D16-D15 -> -0.40261467 | F16: ='1.RETURNS'!D16 -> -0.0042128306 | G16: =G15*EXP(F16) -> 104.01244 | H16: Almost every classical time series model (ARIMA, regression, | T16: What the 4 Data Columns Show
B17: 14 | C17: =_xlfn.NORM.S.INV(RAND()) -> 1.5137007 | D17: =D16+C17 -> 2.732633 | E17: =D17-D16 -> 1.5137007 | F17: ='1.RETURNS'!D17 -> 0.0025967418 | G17: =G16*EXP(F17) -> 104.28289 | H17: VAR) assumes the data is stationary. Using non-stationary data
B18: 15 | C18: =_xlfn.NORM.S.INV(RAND()) -> 0.10159187 | D18: =D17+C18 -> 2.8342248 | E18: =D18-D17 -> 0.10159187 | F18: ='1.RETURNS'!D18 -> -0.019171552 | G18: =G17*EXP(F18) -> 102.30267 | H18: produces 'spurious regressions' — strong-looking correlations | T18: Column | U18: Series | V18: Stationary? | W18: The Point
B19: 16 | C19: =_xlfn.NORM.S.INV(RAND()) -> 1.0141607 | D19: =D18+C19 -> 3.8483856 | E19: =D19-D18 -> 1.0141607 | F19: ='1.RETURNS'!D19 -> -0.020470412 | G19: =G18*EXP(F19) -> 100.22978 | H19: that are purely accidental, not real. | T19: C | U19: Random Shocks (ε) | V19: ✅ Yes | W19: White noise — mean always ≈ 0, std dev always ≈ 1. This is what "well-behaved" data looks like
B20: 17 | C20: =_xlfn.NORM.S.INV(RAND()) -> -0.35889534 | D20: =D19+C20 -> 3.4894902 | E20: =D20-D19 -> -0.35889534 | F20: ='1.RETURNS'!D20 -> -0.0064772079 | G20: =G19*EXP(F20) -> 99.582667 | T20: D | U20: Random Walk | V20: ❌ No | W20: Cumulative sum of shocks. Each step adds to wherever you ended up — it wanders and never comes back
B21: 18 | C21: =_xlfn.NORM.S.INV(RAND()) -> -1.3247293 | D21: =D20+C21 -> 2.1647609 | E21: =D21-D20 -> -1.3247293 | F21: ='1.RETURNS'!D21 -> -0.0097974154 | G21: =G20*EXP(F21) -> 98.611778 | H21: THE RANDOM WALK — THE CLASSIC NON-STATIONARY PROCESS: | T21: E | U21: 1st Diff of Walk | V21: ✅ Yes | W21: Subtracting adjacent Walk values recovers Column C exactly. Differencing cures non-stationarity
B22: 19 | C22: =_xlfn.NORM.S.INV(RAND()) -> 0.10131075 | D22: =D21+C22 -> 2.2660716 | E22: =D22-D21 -> 0.10131075 | F22: ='1.RETURNS'!D22 -> 0.0036193333 | G22: =G21*EXP(F22) -> 98.969333 | T22: F | U22: Simulated Log-Returns | V22: ✅ Yes | W22: Simulated return series — looks statistically identical to Column C. Returns behave like white noise
B23: 20 | C23: =_xlfn.NORM.S.INV(RAND()) -> 1.4929794 | D23: =D22+C23 -> 3.7590511 | E23: =D23-D22 -> 1.4929794 | F23: ='1.RETURNS'!D23 -> -0.0087524506 | G23: =G22*EXP(F23) -> 98.106889 | H23: X_t = X_{t-1} + ε_t (ε_t ~ Normal(0,1)) | T23: G | U23: Simulated Cum. Price Level | V23: ❌ No | W23: Compounding those returns back into a price index — it drifts, just like the random walk in Column D
B24: 21 | C24: =_xlfn.NORM.S.INV(RAND()) -> 0.94881534 | D24: =D23+C24 -> 4.7078664 | E24: =D24-D23 -> 0.94881534 | F24: ='1.RETURNS'!D24 -> -0.014251167 | G24: =G23*EXP(F24) -> 96.718667
B25: 22 | C25: =_xlfn.NORM.S.INV(RAND()) -> -1.7144441 | D25: =D24+C25 -> 2.9934223 | E25: =D25-D24 -> -1.7144441 | F25: ='1.RETURNS'!D25 -> 0.01663348 | G25: =G24*EXP(F25) -> 98.340889 | H25: Each step adds an independent random shock to wherever we were.
B26: 23 | C26: =_xlfn.NORM.S.INV(RAND()) -> -0.34760169 | D26: =D25+C26 -> 2.6458206 | E26: =D26-D25 -> -0.34760169 | F26: ='1.RETURNS'!D26 -> -0.0023279526 | G26: =G25*EXP(F26) -> 98.112222 | H26: The series has no fixed center — it wanders forever. | T26: The 3 Charts Tell the Story Visually
B27: 24 | C27: =_xlfn.NORM.S.INV(RAND()) -> 0.55172045 | D27: =D26+C27 -> 3.1975411 | E27: =D27-D26 -> 0.55172045 | F27: ='1.RETURNS'!D27 -> 0.00093726236 | G27: =G26*EXP(F27) -> 98.204222 | H27: Stock PRICES behave like this. That is why we cannot model prices
B28: 25 | C28: =_xlfn.NORM.S.INV(RAND()) -> -0.30209539 | D28: =D27+C28 -> 2.8954457 | E28: =D28-D27 -> -0.30209539 | F28: ='1.RETURNS'!D28 -> -0.013635752 | G28: =G27*EXP(F28) -> 96.874222 | H28: directly with ARIMA. | T28: Chart 1 — Random Walk (red, top): The line drifts aimlessly — sometimes up, sometimes down, never returning to zero. Hit F9 and it reshapes entirely. No model can predict where it ends up because it has no "center."
B29: 26 | C29: =_xlfn.NORM.S.INV(RAND()) -> -0.071663493 | D29: =D28+C29 -> 2.8237822 | E29: =D29-D28 -> -0.071663493 | F29: ='1.RETURNS'!D29 -> -0.0055921391 | G29: =G28*EXP(F29) -> 96.334
B30: 27 | C30: =_xlfn.NORM.S.INV(RAND()) -> 0.26513136 | D30: =D29+C30 -> 3.0889136 | E30: =D30-D29 -> 0.26513136 | F30: ='1.RETURNS'!D30 -> 0.0013854201 | G30: =G29*EXP(F30) -> 96.467556 | H30: THE FIX — DIFFERENCING: | T30: Chart 2 — Shocks vs. Simulated Returns (blue + green, middle): Both series do the same thing — noisy oscillation around zero. A simulated random process and these simulated returns are statistically indistinguishable. This is the practical implication: returns, not prices, are the right input to your model.
B31: 28 | C31: =_xlfn.NORM.S.INV(RAND()) -> 1.2584753 | D31: =D30+C31 -> 4.3473888 | E31: =D31-D30 -> 1.2584753 | F31: ='1.RETURNS'!D31 -> -0.011016358 | G31: =G30*EXP(F31) -> 95.410667
B32: 29 | C32: =_xlfn.NORM.S.INV(RAND()) -> -1.1470604 | D32: =D31+C32 -> 3.2003284 | E32: =D32-D31 -> -1.1470604 | F32: ='1.RETURNS'!D32 -> 0.0043343887 | G32: =G31*EXP(F32) -> 95.825111 | H32: Take the first difference: ΔX_t = X_t - X_{t-1} = ε_t | T32: Chart 3 — S&P Price Level vs. Returns (red + blue, bottom): The "aha" chart. Same underlying data, split into two forms. The price level (red) drifts — classic non-stationary. The log-returns (blue) bounce near zero — stationary. This is exactly why quant finance works with ln(P_t / P_{t-1}) instead of P_t.
B33: 30 | C33: =_xlfn.NORM.S.INV(RAND()) -> 0.54228608 | D33: =D32+C33 -> 3.7426145 | E33: =D33-D32 -> 0.54228608 | F33: ='1.RETURNS'!D33 -> -0.0059637653 | G33: =G32*EXP(F33) -> 95.255333 | H33: Now you just have the shocks — a stationary white-noise series.
B34: 31 | C34: =_xlfn.NORM.S.INV(RAND()) -> -0.013510658 | D34: =D33+C34 -> 3.7291039 | E34: =D34-D33 -> -0.013510658 | F34: ='1.RETURNS'!D34 -> -0.0027659885 | G34: =G33*EXP(F34) -> 94.992222 | H34: Log-returns ARE this first difference of log-prices.
B35: 32 | C35: =_xlfn.NORM.S.INV(RAND()) -> -0.65176059 | D35: =D34+C35 -> 3.0773433 | E35: =D35-D34 -> -0.65176059 | F35: ='1.RETURNS'!D35 -> -0.005475057 | G35: =G34*EXP(F35) -> 94.473556 | H35: LN(P_t) - LN(P_{t-1}) = LN(P_t / P_{t-1}) = r_t
B36: 33 | C36: =_xlfn.NORM.S.INV(RAND()) -> 1.500549 | D36: =D35+C36 -> 4.5778923 | E36: =D36-D35 -> 1.500549 | F36: ='1.RETURNS'!D36 -> 0.018407344 | G36: =G35*EXP(F36) -> 96.228667 | T36: Takeaway
B37: 34 | C37: =_xlfn.NORM.S.INV(RAND()) -> -0.21145343 | D37: =D36+C37 -> 4.3664388 | E37: =D37-D36 -> -0.21145343 | F37: ='1.RETURNS'!D37 -> 8.7750088e-05 | G37: =G36*EXP(F37) -> 96.237111 | H37: LOOK AT THE DATA TABLE →
B38: 35 | C38: =_xlfn.NORM.S.INV(RAND()) -> 0.32506591 | D38: =D37+C38 -> 4.6915047 | E38: =D38-D37 -> 0.32506591 | F38: ='1.RETURNS'!D38 -> -0.0093562806 | G38: =G37*EXP(F38) -> 95.340889 | H38: Column C = Random shocks (stationary). Always noisy, mean near 0. | T38: Prices are non-stationary random walks. Log-returns are their first difference — stationary white noise. Always model returns, never prices.
B39: 36 | C39: =_xlfn.NORM.S.INV(RAND()) -> -0.32629491 | D39: =D38+C39 -> 4.3652098 | E39: =D39-D38 -> -0.32629491 | F39: ='1.RETURNS'!D39 -> 0.0090814585 | G39: =G38*EXP(F39) -> 96.210667 | H39: Column D = Random walk (cumulative sum). Drifts up or down forever.
B40: 37 | C40: =_xlfn.NORM.S.INV(RAND()) -> 1.1571455 | D40: =D39+C40 -> 5.5223554 | E40: =D40-D39 -> 1.1571455 | F40: ='1.RETURNS'!D40 -> -0.013189794 | G40: =G39*EXP(F40) -> 94.95 | H40: Column E = First diff of the random walk = Column C (exactly). | T40: Press F9 to regenerate the shocks — the random walk reshapes completely every time, but the returns always look the same. That is stationarity.
B41: 38 | C41: =_xlfn.NORM.S.INV(RAND()) -> -0.53375215 | D41: =D40+C41 -> 4.9886032 | E41: =D41-D40 -> -0.53375215 | F41: ='1.RETURNS'!D41 -> 0.0025898212 | G41: =G40*EXP(F41) -> 95.196222 | H41: Column F = simulated log-returns (also stationary, like Column C).
...

Sheet 4.AUTOCORRELATION
B2: SECTION 4 — AUTOCORRELATION: DOES THE PAST PREDICT THE FUTURE?
B3: Obs | C3: Log-Return (%) | D3: Squared Return | E3: Lag-1 Return | F3: Lag-1 Squared
B4: 1 | C4: ='1.RETURNS'!D5*100 -> 0.58848723 | D4: =C4^2 -> 0.34631723 | E4: n/a | F4: n/a | H4: WHAT IS AUTOCORRELATION?
B5: 2 | C5: ='1.RETURNS'!D6*100 -> -0.12113658 | D5: =C5^2 -> 0.01467407 | E5: =C4 -> 0.58848723 | F5: =D4 -> 0.34631723
B6: 3 | C6: ='1.RETURNS'!D7*100 -> 0.66707917 | D6: =C6^2 -> 0.44499462 | E6: =C5 -> -0.12113658 | F6: =D5 -> 0.01467407 | H6: Autocorrelation measures how much today's value is correlated with
B7: 4 | C7: ='1.RETURNS'!D8*100 -> 1.6065487 | D7: =C7^2 -> 2.5809986 | E7: =C6 -> 0.66707917 | F7: =D6 -> 0.44499462 | H7: its own past values. It answers:
B8: 5 | C8: ='1.RETURNS'!D9*100 -> -0.24548761 | D8: =C8^2 -> 0.060264168 | E8: =C7 -> 1.6065487 | F8: =D7 -> 2.5809986 | H8: 'If today's return is large, is tomorrow's also likely large?'
B9: 6 | C9: ='1.RETURNS'!D10*100 -> -0.20112502 | D9: =C9^2 -> 0.040451275 | E9: =C8 -> -0.24548761 | F9: =D8 -> 0.060264168
B10: 7 | C10: ='1.RETURNS'!D11*100 -> 1.5334303 | D10: =C10^2 -> 2.3514084 | E10: =C9 -> -0.20112502 | F10: =D9 -> 0.040451275 | H10: We call this the ACF — Autocorrelation Function.
B11: 8 | C11: ='1.RETURNS'!D12*100 -> 0.88748844 | D11: =C11^2 -> 0.78763574 | E11: =C10 -> 1.5334303 | F11: =D10 -> 2.3514084 | H11: ACF at lag 1 = correlation of r_t with r_{t-1}
B12: 9 | C12: ='1.RETURNS'!D13*100 -> -0.48215906 | D12: =C12^2 -> 0.23247736 | E12: =C11 -> 0.88748844 | F12: =D11 -> 0.78763574 | H12: ACF at lag 2 = correlation of r_t with r_{t-2} ...and so on.
B13: 10 | C13: ='1.RETURNS'!D14*100 -> 0.55124296 | D13: =C13^2 -> 0.30386881 | E13: =C12 -> -0.48215906 | F13: =D12 -> 0.23247736
B14: 11 | C14: ='1.RETURNS'!D15*100 -> -0.42904899 | D14: =C14^2 -> 0.18408304 | E14: =C13 -> 0.55124296 | F14: =D13 -> 0.30386881 | H14: HOW TO COMPUTE IT IN EXCEL:
B15: 12 | C15: ='1.RETURNS'!D16*100 -> -0.42128306 | D15: =C15^2 -> 0.17747942 | E15: =C14 -> -0.42904899 | F15: =D14 -> 0.18408304
B16: 13 | C16: ='1.RETURNS'!D17*100 -> 0.25967418 | D16: =C16^2 -> 0.067430678 | E16: =C15 -> -0.42128306 | F16: =D15 -> 0.17747942 | H16: =CORREL(C5:C253, C4:C252) <- ACF at lag 1 (shift by 1 row)
B17: 14 | C17: ='1.RETURNS'!D18*100 -> -1.9171552 | D17: =C17^2 -> 3.6754841 | E17: =C16 -> 0.25967418 | F17: =D16 -> 0.067430678 | H17: =CORREL(C6:C253, C4:C251) <- ACF at lag 2 (shift by 2 rows)
B18: 15 | C18: ='1.RETURNS'!D19*100 -> -2.0470412 | D18: =C18^2 -> 4.1903776 | E18: =C17 -> -1.9171552 | F18: =D17 -> 3.6754841
B19: 16 | C19: ='1.RETURNS'!D20*100 -> -0.64772079 | D19: =C19^2 -> 0.41954222 | E19: =C18 -> -2.0470412 | F19: =D18 -> 4.1903776 | H19: This is exactly what the ACF TABLE below does.
B20: 17 | C20: ='1.RETURNS'!D21*100 -> -0.97974154 | D20: =C20^2 -> 0.95989349 | E20: =C19 -> -0.64772079 | F20: =D19 -> 0.41954222
B21: 18 | C21: ='1.RETURNS'!D22*100 -> 0.36193333 | D21: =C21^2 -> 0.13099573 | E21: =C20 -> -0.97974154 | F21: =D20 -> 0.95989349 | H21: THE KEY RESULT — TWO ACF TABLES TO COMPARE:
B22: 19 | C22: ='1.RETURNS'!D23*100 -> -0.87524506 | D22: =C22^2 -> 0.76605392 | E22: =C21 -> 0.36193333 | F22: =D21 -> 0.13099573
B23: 20 | C23: ='1.RETURNS'!D24*100 -> -1.4251167 | D23: =C23^2 -> 2.0309575 | E23: =C22 -> -0.87524506 | F23: =D22 -> 0.76605392 | H23: Table 1 = ACF of raw log-returns
B24: 21 | C24: ='1.RETURNS'!D25*100 -> 1.663348 | D24: =C24^2 -> 2.7667266 | E24: =C23 -> -1.4251167 | F24: =D23 -> 2.0309575 | H24: → Lag-1 = −0.168: statistically nonzero but R²≈3% — tiny predictive power.
B25: 22 | C25: ='1.RETURNS'!D26*100 -> -0.23279526 | D25: =C25^2 -> 0.054193635 | E25: =C24 -> 1.663348 | F25: =D24 -> 2.7667266 | H25: → Even so, knowing today's return barely helps predict tomorrow's.
B26: 23 | C26: ='1.RETURNS'!D27*100 -> 0.093726236 | D26: =C26^2 -> 0.0087846073 | E26: =C25 -> -0.23279526 | F26: =D25 -> 0.054193635 | H26: → This is consistent with market efficiency.
B27: 24 | C27: ='1.RETURNS'!D28*100 -> -1.3635752 | D27: =C27^2 -> 1.8593372 | E27: =C26 -> 0.093726236 | F27: =D26 -> 0.0087846073 | H27: → This also means ARIMA will find very little to model.
B28: 25 | C28: ='1.RETURNS'!D29*100 -> -0.55921391 | D28: =C28^2 -> 0.3127202 | E28: =C27 -> -1.3635752 | F28: =D27 -> 1.8593372 | H28: Note: lag-1 at −0.168 exceeds the 0.1 threshold in column E, so it shows 'Not near zero' — accurate. The key point is that R²≈3% makes it economically negligible.
B29: 26 | C29: ='1.RETURNS'!D30*100 -> 0.13854201 | D29: =C29^2 -> 0.019193889 | E29: =C28 -> -0.55921391 | F29: =D28 -> 0.3127202 | H29: Table 2 = ACF of SQUARED returns
B30: 27 | C30: ='1.RETURNS'!D31*100 -> -1.1016358 | D30: =C30^2 -> 1.2136014 | E30: =C29 -> 0.13854201 | F30: =D29 -> 0.019193889 | H30: → Correlations are clearly positive and decay slowly!
B31: 28 | C31: ='1.RETURNS'!D32*100 -> 0.43343887 | D31: =C31^2 -> 0.18786925 | E31: =C30 -> -1.1016358 | F31: =D30 -> 1.2136014 | H31: → The SIZE of today's move predicts the size of tomorrow's move.
B32: 29 | C32: ='1.RETURNS'!D33*100 -> -0.59637653 | D32: =C32^2 -> 0.35566497 | E32: =C31 -> 0.43343887 | F32: =D31 -> 0.18786925 | H32: → This is volatility clustering — structure in the variance.
B33: 30 | C33: ='1.RETURNS'!D34*100 -> -0.27659885 | D33: =C33^2 -> 0.076506926 | E33: =C32 -> -0.59637653 | F33: =D32 -> 0.35566497 | H33: → This is exactly what GARCH is designed to capture.
B34: 31 | C34: ='1.RETURNS'!D35*100 -> -0.5475057 | D34: =C34^2 -> 0.29976249 | E34: =C33 -> -0.27659885 | F34: =D33 -> 0.076506926
B35: 32 | C35: ='1.RETURNS'!D36*100 -> 1.8407344 | D35: =C35^2 -> 3.388303 | E35: =C34 -> -0.5475057 | F35: =D34 -> 0.29976249 | H35: INTERPRETATION:
B36: 33 | C36: ='1.RETURNS'!D37*100 -> 0.0087750088 | D36: =C36^2 -> 7.7000779e-05 | E36: =C35 -> 1.8407344 | F36: =D35 -> 3.388303 | H36: Returns are unpredictable in direction but
B37: 34 | C37: ='1.RETURNS'!D38*100 -> -0.93562806 | D37: =C37^2 -> 0.87539986 | E37: =C36 -> 0.0087750088 | F37: =D36 -> 7.7000779e-05 | H37: predictable in magnitude.
B38: 35 | C38: ='1.RETURNS'!D39*100 -> 0.90814585 | D38: =C38^2 -> 0.82472889 | E38: =C37 -> -0.93562806 | F38: =D37 -> 0.87539986 | H38: That gap between the two tables is the entire
B39: 36 | C39: ='1.RETURNS'!D40*100 -> -1.3189794 | D39: =C39^2 -> 1.7397068 | E39: =C38 -> 0.90814585 | F39: =D38 -> 0.82472889 | H39: intellectual justification for GARCH modeling.
B40: 37 | C40: ='1.RETURNS'!D41*100 -> 0.25898212 | D40: =C40^2 -> 0.067071739 | E40: =C39 -> -1.3189794 | F40: =D39 -> 1.7397068
B41: 38 | C41: ='1.RETURNS'!D42*100 -> -1.8806259 | D41: =C41^2 -> 3.5367537 | E41: =C40 -> 0.25898212 | F41: =D40 -> 0.067071739
...

Sheet 5.ARIMA
B1: φ (AR): | C1: 0.95 | D1: θ (MA): | E1: 0.7 | J1: φ̂ (from simulated return series): | K1: =CORREL('1.RETURNS'!D6:D254,'1.RETURNS'!D5:D253) -> -0.16792779 | M1: θ̂ (MA1, simulated data): | N1: =(1-SQRT(1-4*K1^2))/(2*K1) -> -0.17295084
B2: SECTION 5 — ARIMA: MODELING THE MEAN OF A TIME SERIES | J2: SIMULATED RETURN SERIES — AR(1) APPLIED [Illustrative, 2023 calendar] | M2: MA(1) & ARIMA(1,0,1) APPLIED TO SIMULATED RETURN SERIES
A3: ε (AR) | B3: Obs | C3: AR(1) Simulation | D3: MA(1) Simulation | E3: Random Walk | F3: 1st Diff (= shock) | G3: ε (MA) | H3: ARIMA(1,0,1) | J3: Actual Return (×100 = % daily) | K3: AR(1) Fitted: φ̂ × r(t−1) | L3: Residual/Error: r(t) − φ̂×r(t−1) | M3: MA(1) ε̂(t) [helper] | N3: MA(1) Fitted: θ̂×ε̂(t−1) | O3: ARIMA ε̂(t) [helper] | P3: ARIMA(1,0,1) Fitted: φ̂×r(t−1)+θ̂×ε̂(t−1)
A4: n/a | B4: =ROW()-3 -> 1 | C4: =_xlfn.NORM.INV(RAND(),0,1) -> -0.34384148 | D4: =G4 -> -0.20850132 | E4: =_xlfn.NORM.INV(RAND(),0,1) -> 1.2479159 | F4: n/a | G4: =_xlfn.NORM.INV(RAND(),0,1) -> -0.20850132 | H4: =G4 -> -0.20850132 | I4: ▌ ARIMA(p, d, q) — MODELING THE MEAN | J4: ='1.RETURNS'!D5*100 -> 0.58848723 | K4: n/a | L4: n/a | M4: =J4 -> 0.58848723 | N4: n/a | O4: =J4 -> 0.58848723 | P4: n/a
A5: =_xlfn.NORM.INV(RAND(),0,1) -> -1.2694067 | B5: =ROW()-3 -> 2 | C5: =$C$1*C4+A5 -> -1.5960561 | D5: =G5+$E$1*G4 -> -0.81309841 | E5: =E4+F5 -> 1.0909878 | F5: =_xlfn.NORM.INV(RAND(),0,1) -> -0.15692813 | G5: =_xlfn.NORM.INV(RAND(),0,1) -> -0.66714748 | H5: =$C$1*H4+G5+$E$1*G4 -> -1.0111747 | I5: ARIMA combines three tools into one model to capture structure in the conditional mean: | J5: ='1.RETURNS'!D6*100 -> -0.12113658 | K5: =$K$1*J4 -> -0.098823359 | L5: =J5-K5 -> -0.022313217 | M5: =J5-$N$1*M4 -> -0.019357214 | N5: =$N$1*M4 -> -0.10177936 | O5: =J5-$K$1*J4-$N$1*O4 -> 0.079466145 | P5: =$K$1*J4+$N$1*O4 -> -0.20060272
A6: =_xlfn.NORM.INV(RAND(),0,1) -> -1.0917576 | B6: =ROW()-3 -> 3 | C6: =$C$1*C5+A6 -> -2.6080109 | D6: =G6+$E$1*G5 -> 0.30876878 | E6: =E5+F6 -> 0.75367204 | F6: =_xlfn.NORM.INV(RAND(),0,1) -> -0.33731573 | G6: =_xlfn.NORM.INV(RAND(),0,1) -> 0.77577201 | H6: =$C$1*H5+G6+$E$1*G5 -> -0.65184716 | I6: AR = AutoRegressive · today's value depends on past VALUES of y | J6: ='1.RETURNS'!D7*100 -> 0.66707917 | K6: =$K$1*J5 -> 0.020342197 | L6: =J6-K6 -> 0.64673698 | M6: =J6-$N$1*M5 -> 0.66373133 | N6: =$N$1*M5 -> 0.0033478464 | O6: =J6-$K$1*J5-$N$1*O5 -> 0.66048071 | P6: =$K$1*J5+$N$1*O5 -> 0.0065984605 | Q6: =J6-'5.ARIMA'!P6 -> 0.66048071
A7: =_xlfn.NORM.INV(RAND(),0,1) -> -0.42388598 | B7: =ROW()-3 -> 4 | C7: =$C$1*C6+A7 -> -2.9014963 | D7: =G7+$E$1*G6 -> 0.61738419 | E7: =E6+F7 -> 0.33389596 | F7: =_xlfn.NORM.INV(RAND(),0,1) -> -0.41977609 | G7: =_xlfn.NORM.INV(RAND(),0,1) -> 0.074343782 | H7: =$C$1*H6+G7+$E$1*G6 -> -0.0018706073 | I7: I = Integrated · how many times the series is differenced first | J7: ='1.RETURNS'!D8*100 -> 1.6065487 | K7: =$K$1*J6 -> -0.11202113 | L7: =J7-K7 -> 1.7185698 | M7: =J7-$N$1*M6 -> 1.7213416 | N7: =$N$1*M6 -> -0.11479289 | O7: =J7-$K$1*J6-$N$1*O6 -> 1.8328005 | P7: =$K$1*J6+$N$1*O6 -> -0.22625183
A8: =_xlfn.NORM.INV(RAND(),0,1) -> 0.23633082 | B8: =ROW()-3 -> 5 | C8: =$C$1*C7+A8 -> -2.5200907 | D8: =G8+$E$1*G7 -> -0.57982611 | E8: =E7+F8 -> -0.36314519 | F8: =_xlfn.NORM.INV(RAND(),0,1) -> -0.69704115 | G8: =_xlfn.NORM.INV(RAND(),0,1) -> -0.63186676 | H8: =$C$1*H7+G8+$E$1*G7 -> -0.58160319 | I8: MA = Moving Average · today's value depends on past SHOCKS (ε) | J8: ='1.RETURNS'!D9*100 -> -0.24548761 | K8: =$K$1*J7 -> -0.26978416 | L8: =J8-K8 -> 0.024296549 | M8: =J8-$N$1*M7 -> 0.052219858 | N8: =$N$1*M7 -> -0.29770747 | O8: =J8-$K$1*J7-$N$1*O7 -> 0.34128094 | P8: =$K$1*J7+$N$1*O7 -> -0.58676855
A9: =_xlfn.NORM.INV(RAND(),0,1) -> 1.378673 | B9: =ROW()-3 -> 6 | C9: =$C$1*C8+A9 -> -1.0154132 | D9: =G9+$E$1*G8 -> -0.227681 | E9: =E8+F9 -> 0.82987368 | F9: =_xlfn.NORM.INV(RAND(),0,1) -> 1.1930189 | G9: =_xlfn.NORM.INV(RAND(),0,1) -> 0.21462573 | H9: =$C$1*H8+G9+$E$1*G8 -> -0.78020403 | I9: Notation: ARIMA(p, d, q) where p = # AR lags, d = # differences, q = # MA lags | J9: ='1.RETURNS'!D10*100 -> -0.20112502 | K9: =$K$1*J8 -> 0.041224192 | L9: =J9-K9 -> -0.24234921 | M9: =J9-$N$1*M8 -> -0.19209355 | N9: =$N$1*M8 -> -0.0090314685 | O9: =J9-$K$1*J8-$N$1*O8 -> -0.18332439 | P9: =$K$1*J8+$N$1*O8 -> -0.017800634
A10: =_xlfn.NORM.INV(RAND(),0,1) -> -1.716232 | B10: =ROW()-3 -> 7 | C10: =$C$1*C9+A10 -> -2.6808745 | D10: =G10+$E$1*G9 -> -0.42288065 | E10: =E9+F10 -> 1.0368187 | F10: =_xlfn.NORM.INV(RAND(),0,1) -> 0.20694501 | G10: =_xlfn.NORM.INV(RAND(),0,1) -> -0.57311866 | H10: =$C$1*H9+G10+$E$1*G9 -> -1.1640745 | J10: ='1.RETURNS'!D11*100 -> 1.5334303 | K10: =$K$1*J9 -> 0.03377448 | L10: =J10-K10 -> 1.4996558 | M10: =J10-$N$1*M9 -> 1.5002075 | N10: =$N$1*M9 -> 0.033222742 | O10: =J10-$K$1*J9-$N$1*O9 -> 1.4679497 | P10: =$K$1*J9+$N$1*O9 -> 0.065480587
A11: =_xlfn.NORM.INV(RAND(),0,1) -> -0.57312432 | B11: =ROW()-3 -> 8 | C11: =$C$1*C10+A11 -> -3.1199551 | D11: =G11+$E$1*G10 -> -1.3213294 | E11: =E10+F11 -> 1.4099151 | F11: =_xlfn.NORM.INV(RAND(),0,1) -> 0.37309645 | G11: =_xlfn.NORM.INV(RAND(),0,1) -> -0.9201463 | H11: =$C$1*H10+G11+$E$1*G10 -> -2.4272001 | I11: ▌ PART A — AR(p): AUTOREGRESSIVE MODEL [Column C] | J11: ='1.RETURNS'!D12*100 -> 0.88748844 | K11: =$K$1*J10 -> -0.25750555 | L11: =J11-K11 -> 1.144994 | M11: =J11-$N$1*M10 -> 1.1469506 | N11: =$N$1*M10 -> -0.25946215 | O11: =J11-$K$1*J10-$N$1*O10 -> 1.3988771 | P11: =$K$1*J10+$N$1*O10 -> -0.51138868
A12: =_xlfn.NORM.INV(RAND(),0,1) -> 0.27117501 | B12: =ROW()-3 -> 9 | C12: =$C$1*C11+A12 -> -2.6927823 | D12: =G12+$E$1*G11 -> -1.2866289 | E12: =E11+F12 -> 2.2251914 | F12: =_xlfn.NORM.INV(RAND(),0,1) -> 0.81527623 | G12: =_xlfn.NORM.INV(RAND(),0,1) -> -0.6425265 | H12: =$C$1*H11+G12+$E$1*G11 -> -3.592469 | I12: AR(p): today's value is a weighted sum of the last p values plus white noise ε(t): | J12: ='1.RETURNS'!D13*100 -> -0.48215906 | K12: =$K$1*J11 -> -0.14903397 | L12: =J12-K12 -> -0.33312509 | M12: =J12-$N$1*M11 -> -0.28379299 | N12: =$N$1*M11 -> -0.19836607 | O12: =J12-$K$1*J11-$N$1*O11 -> -0.091188117 | P12: =$K$1*J11+$N$1*O11 -> -0.39097095
A13: =_xlfn.NORM.INV(RAND(),0,1) -> 0.099459566 | B13: =ROW()-3 -> 10 | C13: =$C$1*C12+A13 -> -2.4586836 | D13: =G13+$E$1*G12 -> -2.0983316 | E13: =E12+F13 -> 0.83744536 | F13: =_xlfn.NORM.INV(RAND(),0,1) -> -1.387746 | G13: =_xlfn.NORM.INV(RAND(),0,1) -> -1.6485631 | H13: =$C$1*H12+G13+$E$1*G12 -> -5.5111772 | I13: y(t) = φ₁·y(t−1) + φ₂·y(t−2) + ··· + φₚ·y(t−p) + ε(t) ← general AR(p) | J13: ='1.RETURNS'!D14*100 -> 0.55124296 | K13: =$K$1*J12 -> 0.080967905 | L13: =J13-K13 -> 0.47027506 | M13: =J13-$N$1*M12 -> 0.50216073 | N13: =$N$1*M12 -> 0.049082237 | O13: =J13-$K$1*J12-$N$1*O12 -> 0.454504 | P13: =$K$1*J12+$N$1*O12 -> 0.096738966
A14: =_xlfn.NORM.INV(RAND(),0,1) -> -0.13334775 | B14: =ROW()-3 -> 11 | C14: =$C$1*C13+A14 -> -2.4690972 | D14: =G14+$E$1*G13 -> -0.19202373 | E14: =E13+F14 -> 1.1382691 | F14: =_xlfn.NORM.INV(RAND(),0,1) -> 0.30082375 | G14: =_xlfn.NORM.INV(RAND(),0,1) -> 0.9619704 | H14: =$C$1*H13+G14+$E$1*G13 -> -5.427642 | I14: AR(1) simulated in Column C [φ = 0.7, stored in C1 — change to experiment]: | J14: ='1.RETURNS'!D15*100 -> -0.42904899 | K14: =$K$1*J13 -> -0.092569011 | L14: =J14-K14 -> -0.33647998 | M14: =J14-$N$1*M13 -> -0.34219987 | N14: =$N$1*M13 -> -0.086849121 | O14: =J14-$K$1*J13-$N$1*O13 -> -0.25787313 | P14: =$K$1*J13+$N$1*O13 -> -0.17117586
A15: =_xlfn.NORM.INV(RAND(),0,1) -> -0.34291639 | B15: =ROW()-3 -> 12 | C15: =$C$1*C14+A15 -> -2.6885587 | D15: =G15+$E$1*G14 -> -0.15282932 | E15: =E14+F15 -> 1.4377766 | F15: =_xlfn.NORM.INV(RAND(),0,1) -> 0.29950749 | G15: =_xlfn.NORM.INV(RAND(),0,1) -> -0.8262086 | H15: =$C$1*H14+G15+$E$1*G14 -> -5.3090893 | I15: y(t) = φ · y(t−1) + ε(t) | J15: ='1.RETURNS'!D16*100 -> -0.42128306 | K15: =$K$1*J14 -> 0.072049248 | L15: =J15-K15 -> -0.49333231 | M15: =J15-$N$1*M14 -> -0.48046682 | N15: =$N$1*M14 -> 0.059183756 | O15: =J15-$K$1*J14-$N$1*O14 -> -0.53793168 | P15: =$K$1*J14+$N$1*O14 -> 0.11664862
A16: =_xlfn.NORM.INV(RAND(),0,1) -> -0.55069572 | B16: =ROW()-3 -> 13 | C16: =$C$1*C15+A16 -> -3.1048265 | D16: =G16+$E$1*G15 -> -0.66031733 | E16: =E15+F16 -> 0.5561792 | F16: =_xlfn.NORM.INV(RAND(),0,1) -> -0.88159741 | G16: =_xlfn.NORM.INV(RAND(),0,1) -> -0.081971312 | H16: =$C$1*H15+G16+$E$1*G15 -> -5.7039521 | I16: ↳ Excel cell: C5 = $C$1 × C4 + A5 [C1 = φ = 0.7, C4 = y(t−1), A5 = ε(t)] | J16: ='1.RETURNS'!D17*100 -> 0.25967418 | K16: =$K$1*J15 -> 0.070745132 | L16: =J16-K16 -> 0.18892904 | M16: =J16-$N$1*M15 -> 0.17657704 | N16: =$N$1*M15 -> 0.083097141 | O16: =J16-$K$1*J15-$N$1*O15 -> 0.095893307 | P16: =$K$1*J15+$N$1*O15 -> 0.16378087
A17: =_xlfn.NORM.INV(RAND(),0,1) -> -0.78137756 | B17: =ROW()-3 -> 14 | C17: =$C$1*C16+A17 -> -3.7309628 | D17: =G17+$E$1*G16 -> -0.04090451 | E17: =E16+F17 -> 0.44982235 | F17: =_xlfn.NORM.INV(RAND(),0,1) -> -0.10635684 | G17: =_xlfn.NORM.INV(RAND(),0,1) -> 0.016475408 | H17: =$C$1*H16+G17+$E$1*G16 -> -5.459659 | I17: Persistence: φ = 0.7 means 70% of last period's level carries into today's value. | J17: ='1.RETURNS'!D18*100 -> -1.9171552 | K17: =$K$1*J16 -> -0.04360651 | L17: =J17-K17 -> -1.8735487 | M17: =J17-$N$1*M16 -> -1.8866161 | N17: =$N$1*M16 -> -0.030539147 | O17: =J17-$K$1*J16-$N$1*O16 -> -1.8569639 | P17: =$K$1*J16+$N$1*O16 -> -0.060191338
A18: =_xlfn.NORM.INV(RAND(),0,1) -> 1.6142582 | B18: =ROW()-3 -> 15 | C18: =$C$1*C17+A18 -> -1.9301565 | D18: =G18+$E$1*G17 -> 0.21319264 | E18: =E17+F18 -> -0.2710434 | F18: =_xlfn.NORM.INV(RAND(),0,1) -> -0.72086575 | G18: =_xlfn.NORM.INV(RAND(),0,1) -> 0.20165986 | H18: =$C$1*H17+G18+$E$1*G17 -> -4.9734834 | I18: Stability: ||φ|| < 1 required for stationarity. At φ = 1 the process becomes a random walk. | J18: ='1.RETURNS'!D19*100 -> -2.0470412 | K18: =$K$1*J17 -> 0.32194363 | L18: =J18-K18 -> -2.3689848 | M18: =J18-$N$1*M17 -> -2.373333 | N18: =$N$1*M17 -> 0.32629184 | O18: =J18-$K$1*J17-$N$1*O17 -> -2.6901483 | P18: =$K$1*J17+$N$1*O17 -> 0.6431071
A19: =_xlfn.NORM.INV(RAND(),0,1) -> 1.2444162 | B19: =ROW()-3 -> 16 | C19: =$C$1*C18+A19 -> -0.58923247 | D19: =G19+$E$1*G18 -> 0.23847845 | E19: =E18+F19 -> 1.3712497 | F19: =_xlfn.NORM.INV(RAND(),0,1) -> 1.6422931 | G19: =_xlfn.NORM.INV(RAND(),0,1) -> 0.097316551 | H19: =$C$1*H18+G19+$E$1*G18 -> -4.4863308 | I19: Long-run variance: Var[y(t)] = σ²_ε / (1 − φ²) [grows as φ → 1] | J19: ='1.RETURNS'!D20*100 -> -0.64772079 | K19: =$K$1*J18 -> 0.3437551 | L19: =J19-K19 -> -0.99147589 | M19: =J19-$N$1*M18 -> -1.0581907 | N19: =$N$1*M18 -> 0.41046994 | O19: =J19-$K$1*J18-$N$1*O18 -> -1.4567393 | P19: =$K$1*J18+$N$1*O18 -> 0.80901851
A20: =_xlfn.NORM.INV(RAND(),0,1) -> 0.36738545 | B20: =ROW()-3 -> 17 | C20: =$C$1*C19+A20 -> -0.1923854 | D20: =G20+$E$1*G19 -> 0.51097909 | E20: =E19+F20 -> 1.6271123 | F20: =_xlfn.NORM.INV(RAND(),0,1) -> 0.25586258 | G20: =_xlfn.NORM.INV(RAND(),0,1) -> 0.44285751 | H20: =$C$1*H19+G20+$E$1*G19 -> -3.7510352 | J20: ='1.RETURNS'!D21*100 -> -0.97974154 | K20: =$K$1*J19 -> 0.10877032 | L20: =J20-K20 -> -1.0885119 | M20: =J20-$N$1*M19 -> -1.1627565 | N20: =$N$1*M19 -> 0.18301498 | O20: =J20-$K$1*J19-$N$1*O19 -> -1.3404562 | P20: =$K$1*J19+$N$1*O19 -> 0.36071461
A21: =_xlfn.NORM.INV(RAND(),0,1) -> -0.25991807 | B21: =ROW()-3 -> 18 | C21: =$C$1*C20+A21 -> -0.44268421 | D21: =G21+$E$1*G20 -> 0.72194793 | E21: =E20+F21 -> 1.8562381 | F21: =_xlfn.NORM.INV(RAND(),0,1) -> 0.22912582 | G21: =_xlfn.NORM.INV(RAND(),0,1) -> 0.41194767 | H21: =$C$1*H20+G21+$E$1*G20 -> -2.8415355 | I21: ▌ PART B — MA(q): MOVING AVERAGE MODEL [Column D] | J21: ='1.RETURNS'!D22*100 -> 0.36193333 | K21: =$K$1*J20 -> 0.16452583 | L21: =J21-K21 -> 0.1974075 | M21: =J21-$N$1*M20 -> 0.16083361 | N21: =$N$1*M20 -> 0.20109972 | O21: =J21-$K$1*J20-$N$1*O20 -> -0.034425521 | P21: =$K$1*J20+$N$1*O20 -> 0.39635885
A22: =_xlfn.NORM.INV(RAND(),0,1) -> -0.73406048 | B22: =ROW()-3 -> 19 | C22: =$C$1*C21+A22 -> -1.1546105 | D22: =G22+$E$1*G21 -> 0.53769054 | E22: =E21+F22 -> 2.4329261 | F22: =_xlfn.NORM.INV(RAND(),0,1) -> 0.57668799 | G22: =_xlfn.NORM.INV(RAND(),0,1) -> 0.24932717 | H22: =$C$1*H21+G22+$E$1*G21 -> -2.1617682 | I22: MA(q): today's value is a weighted sum of the current and last q−1 shocks: | J22: ='1.RETURNS'!D23*100 -> -0.87524506 | K22: =$K$1*J21 -> -0.060778663 | L22: =J22-K22 -> -0.8144664 | M22: =J22-$N$1*M21 -> -0.84742875 | N22: =$N$1*M21 -> -0.027816308 | O22: =J22-$K$1*J21-$N$1*O21 -> -0.82042032 | P22: =$K$1*J21+$N$1*O21 -> -0.05482474
A23: =_xlfn.NORM.INV(RAND(),0,1) -> 0.15752506 | B23: =ROW()-3 -> 20 | C23: =$C$1*C22+A23 -> -0.93935489 | D23: =G23+$E$1*G22 -> -0.26141869 | E23: =E22+F23 -> 2.8571091 | F23: =_xlfn.NORM.INV(RAND(),0,1) -> 0.42418298 | G23: =_xlfn.NORM.INV(RAND(),0,1) -> -0.43594771 | H23: =$C$1*H22+G23+$E$1*G22 -> -2.3150985 | I23: y(t) = ε(t) + θ₁·ε(t−1) + θ₂·ε(t−2) + ··· + θ_q·ε(t−q) ← general MA(q) | J23: ='1.RETURNS'!D24*100 -> -1.4251167 | K23: =$K$1*J22 -> 0.14697797 | L23: =J23-K23 -> -1.5720946 | M23: =J23-$N$1*M22 -> -1.5716802 | N23: =$N$1*M22 -> 0.14656352 | O23: =J23-$K$1*J22-$N$1*O22 -> -1.713987 | P23: =$K$1*J22+$N$1*O22 -> 0.28887035
A24: =_xlfn.NORM.INV(RAND(),0,1) -> 0.002043596 | B24: =ROW()-3 -> 21 | C24: =$C$1*C23+A24 -> -0.89034354 | D24: =G24+$E$1*G23 -> -0.19252911 | E24: =E23+F24 -> 2.6923863 | F24: =_xlfn.NORM.INV(RAND(),0,1) -> -0.16472278 | G24: =_xlfn.NORM.INV(RAND(),0,1) -> 0.11263429 | H24: =$C$1*H23+G24+$E$1*G23 -> -2.3918726 | I24: MA(1) simulated in Column D [θ = 0.6, stored in E1 — change to experiment]: | J24: ='1.RETURNS'!D25*100 -> 1.663348 | K24: =$K$1*J23 -> 0.23931669 | L24: =J24-K24 -> 1.4240313 | M24: =J24-$N$1*M23 -> 1.3915246 | N24: =$N$1*M23 -> 0.27182341 | O24: =J24-$K$1*J23-$N$1*O23 -> 1.1275958 | P24: =$K$1*J23+$N$1*O23 -> 0.53575218
A25: =_xlfn.NORM.INV(RAND(),0,1) -> 0.70367625 | B25: =ROW()-3 -> 22 | C25: =$C$1*C24+A25 -> -0.14215011 | D25: =G25+$E$1*G24 -> 0.10436858 | E25: =E24+F25 -> 1.4931956 | F25: =_xlfn.NORM.INV(RAND(),0,1) -> -1.1991907 | G25: =_xlfn.NORM.INV(RAND(),0,1) -> 0.025524582 | H25: =$C$1*H24+G25+$E$1*G24 -> -2.1679104 | I25: y(t) = ε(t) + θ · ε(t−1) | J25: ='1.RETURNS'!D26*100 -> -0.23279526 | K25: =$K$1*J24 -> -0.27932235 | L25: =J25-K25 -> 0.046527087 | M25: =J25-$N$1*M24 -> 0.0078700881 | N25: =$N$1*M24 -> -0.24066535 | O25: =J25-$K$1*J24-$N$1*O24 -> 0.24154574 | P25: =$K$1*J24+$N$1*O24 -> -0.474341
A26: =_xlfn.NORM.INV(RAND(),0,1) -> 0.097745077 | B26: =ROW()-3 -> 23 | C26: =$C$1*C25+A26 -> -0.037297532 | D26: =G26+$E$1*G25 -> 0.56228399 | E26: =E25+F26 -> 1.6501406 | F26: =_xlfn.NORM.INV(RAND(),0,1) -> 0.15694493 | G26: =_xlfn.NORM.INV(RAND(),0,1) -> 0.54441679 | H26: =$C$1*H25+G26+$E$1*G25 -> -1.4972309 | I26: ↳ Excel cell: D5 = G5 + $E$1 × G4 [G5 = ε(t), E1 = θ = 0.6, G4 = ε(t−1)] | J26: ='1.RETURNS'!D27*100 -> 0.093726236 | K26: =$K$1*J25 -> 0.039092794 | L26: =J26-K26 -> 0.054633442 | M26: =J26-$N$1*M25 -> 0.095087374 | N26: =$N$1*M25 -> -0.0013611384 | O26: =J26-$K$1*J25-$N$1*O25 -> 0.096408981 | P26: =$K$1*J25+$N$1*O25 -> -0.0026827448
A27: =_xlfn.NORM.INV(RAND(),0,1) -> 0.59531868 | B27: =ROW()-3 -> 24 | C27: =$C$1*C26+A27 -> 0.55988603 | D27: =G27+$E$1*G26 -> -0.88451142 | E27: =E26+F27 -> 1.8611612 | F27: =_xlfn.NORM.INV(RAND(),0,1) -> 0.21102062 | G27: =_xlfn.NORM.INV(RAND(),0,1) -> -1.2656032 | H27: =$C$1*H26+G27+$E$1*G26 -> -2.3068808 | I27: Intuition: today's value = current shock + a fraction of yesterday's shock. | J27: ='1.RETURNS'!D28*100 -> -1.3635752 | K27: =$K$1*J26 -> -0.015739239 | L27: =J27-K27 -> -1.3478359 | M27: =J27-$N$1*M26 -> -1.3471297 | N27: =$N$1*M26 -> -0.016445441 | O27: =J27-$K$1*J26-$N$1*O26 -> -1.3311619 | P27: =$K$1*J26+$N$1*O26 -> -0.032413254
A28: =_xlfn.NORM.INV(RAND(),0,1) -> -1.2092017 | B28: =ROW()-3 -> 25 | C28: =$C$1*C27+A28 -> -0.67731 | D28: =G28+$E$1*G27 -> 0.78078352 | E28: =E27+F28 -> 1.4742377 | F28: =_xlfn.NORM.INV(RAND(),0,1) -> -0.38692347 | G28: =_xlfn.NORM.INV(RAND(),0,1) -> 1.6667057 | H28: =$C$1*H27+G28+$E$1*G27 -> -1.4107532 | I28: Short memory: the MA effect vanishes completely after exactly q lags (finite impulse response). | J28: ='1.RETURNS'!D29*100 -> -0.55921391 | K28: =$K$1*J27 -> 0.22898216 | L28: =J28-K28 -> -0.78819607 | M28: =J28-$N$1*M27 -> -0.79220113 | N28: =$N$1*M27 -> 0.23298722 | O28: =J28-$K$1*J27-$N$1*O27 -> -1.0184216 | P28: =$K$1*J27+$N$1*O27 -> 0.45920773
A29: =_xlfn.NORM.INV(RAND(),0,1) -> -2.6232188 | B29: =ROW()-3 -> 26 | C29: =$C$1*C28+A29 -> -3.2666633 | D29: =G29+$E$1*G28 -> 1.2725625 | E29: =E28+F29 -> 2.5627955 | F29: =_xlfn.NORM.INV(RAND(),0,1) -> 1.0885577 | G29: =_xlfn.NORM.INV(RAND(),0,1) -> 0.10586846 | H29: =$C$1*H28+G29+$E$1*G28 -> -0.067653083 | I29: Always stationary: any value of θ works — no stability constraint required (unlike AR). | J29: ='1.RETURNS'!D30*100 -> 0.13854201 | K29: =$K$1*J28 -> 0.093907555 | L29: =J29-K29 -> 0.044634457 | M29: =J29-$N$1*M28 -> 0.0015301588 | N29: =$N$1*M28 -> 0.13701185 | O29: =J29-$K$1*J28-$N$1*O28 -> -0.13150242 | P29: =$K$1*J28+$N$1*O28 -> 0.27004444
A30: =_xlfn.NORM.INV(RAND(),0,1) -> 0.13872704 | B30: =ROW()-3 -> 27 | C30: =$C$1*C29+A30 -> -2.9646031 | D30: =G30+$E$1*G29 -> 0.018942366 | E30: =E29+F30 -> 2.8278337 | F30: =_xlfn.NORM.INV(RAND(),0,1) -> 0.26503828 | G30: =_xlfn.NORM.INV(RAND(),0,1) -> -0.055165559 | H30: =$C$1*H29+G30+$E$1*G29 -> -0.045328062 | I30: Long-run variance: Var[y(t)] = σ²_ε · (1 + θ²) | J30: ='1.RETURNS'!D31*100 -> -1.1016358 | K30: =$K$1*J29 -> -0.023265053 | L30: =J30-K30 -> -1.0783707 | M30: =J30-$N$1*M29 -> -1.1013711 | N30: =$N$1*M29 -> -0.00026464225 | O30: =J30-$K$1*J29-$N$1*O29 -> -1.1011142 | P30: =$K$1*J29+$N$1*O29 -> -0.00052159844
